Workbook

Sheet _Listas
A1: Componente | B1: Estado Cumplimiento | C1: Nivel Hallazgo | D1: Estado Hallazgo | E1: Tipo Evidencia | F1: Frecuencia | G1: Etapa | H1: Tipo Obligacion | I1: Nivel Certeza | J1: Si No | K1: Estado Documental | L1: Tipo Residuo | M1: Unidad | N1: Riesgo Ambiental | O1: Responsables | P1: Mes auditoría | Q1: Temas capacitación
A2: Autorizaciones y permisos | B2: Cumple | C2: Crítico | D2: Abierto | E2: Fotografía | F2: Diaria | G2: Instalación | H2: Obligación contenida en el Plan de Manejo | I2: Expreso en el Plan de Manejo | J2: Sí | K2: Vigente | L2: Residuos domiciliarios | M2: kg | N2: Alto | O2: Encargado ambiental | P2: 05-2026 | Q2: Buenas prácticas ambientales
A3: Condiciones generales de operación | B3: Cumple parcialmente | C3: Mayor | D3: En tratamiento | E3: Acta | F3: Semanal | G3: Operación | H3: Exigencia legal o reglamentaria | I3: Derivado del Plan de Manejo | J3: No | K3: Por vencer en 30 días | L3: RCD | M3: ton | N3: Medio | O3: Administrador de obra | P3: 06-2026 | Q3: Manejo de residuos
A4: Orden y limpieza | B4: No cumple | C4: Menor | D4: Cerrado | E4: Certificado | F4: Quincenal | G4: Mantenimiento | H4: Compromiso contractual | I4: Norma o permiso aplicable | K4: Por vencer en 60 días | L4: Chatarra | M4: m³ | N4: Bajo | O4: Jefe de faena | P4: 07-2026 | Q4: Residuos peligrosos
A5: Ocupación del área | B5: No aplica | C5: Observación | D5: Verificado | E5: Resolución | F5: Mensual | G5: Cierre | H5: Buena práctica ambiental | I5: Requiere validación | K5: Vencido | L5: Madera | M5: L | N5: No aplica | O5: Supervisor de área | P5: 08-2026 | Q5: Control de derrames
A6: Control de accesos | B6: Pendiente de verificación | C6: Buena práctica | D6: Reabierto | E6: Guía de transporte | F6: Trimestral | G6: Todas las etapas | H6: Antecedente documental pendiente | K6: En trámite | L6: Plásticos no contaminados | M6: unidad | O6: Inspector Fiscal | P6: 09-2026 | Q6: Protección del agua
A7: Flujo y tránsito de maquinaria | B7: En proceso de regularización | C7: Sin hallazgo | E7: Manifiesto | F7: Semestral | K7: No disponible | L7: Aceite usado | M7: bolsa | O7: Contratista RESPEL | P7: 10-2026 | Q7: Protección del río Ventisquero
A8: Velocidad máxima | E8: Informe | F8: Anual | K8: No aplica | L8: Filtros | M8: contenedor | O8: Otro | P8: 11-2026 | Q8: Flora y fauna
A9: Funcionamiento de motores | E9: Registro | F9: Eventual | L9: Baterías | P9: 12-2026 | Q9: Prohibición de caza y alimentación de fauna
A10: Emisiones atmosféricas | E10: Lista de asistencia | L10: Ropa contaminada | P10: 01-2027 | Q10: Patrimonio arqueológico
A11: Polvo y material particulado | E11: Libro de Comunicaciones | L11: Tierra contaminada | P11: 02-2027 | Q11: Relación con la comunidad
A12: Ruido | E12: Otro | L12: Huaipe | P12: 03-2027 | Q12: Control de velocidad
A13: Generador eléctrico | L13: Envases contaminados | P13: 04-2027 | Q13: Uso de hojas de seguridad
A14: Combustibles | L14: Tubos fluorescentes | P14: 05-2027 | Q14: Procedimiento ante emergencias ambientales
A15: Sustancias peligrosas | L15: Otros RESPEL | P15: 06-2027
A16: Derrames y contingencias | P16: 07-2027
A17: Mantención mecánica | P17: 08-2027
A18: Protección del suelo | P18: 09-2027
A19: Protección del agua | P19: 10-2027
A20: Río Ventisquero | P20: 11-2027
A21: Baños químicos | P21: 12-2027
A22: Fosas sépticas | P22: 01-2028
A23: Agua potable | P23: 02-2028
A24: Agua envasada | P24: 03-2028
A25: Residuos domiciliarios y asimilables | P25: 04-2028
A26: Residuos industriales no peligrosos | P26: 05-2028
A27: Residuos peligrosos
A28: Bodega RESPEL
A29: Patio de salvataje
A30: Segregación de residuos
A31: Transporte y disposición final
A32: Declaración RCD
A33: Declaración anual de emisiones
A34: Control de plagas
A35: Sanitización y desratización
A36: Flora y fauna
A37: Prohibición de caza y alimentación de fauna
A38: Patrimonio arqueológico
... A46: Abandono y cierre de la instalación

Sheet Portada
A1: AUDITORÍA TÉCNICO-AMBIENTAL MENSUAL
A2: Plan de Manejo Ambiental Específico para Instalación de Faenas Río Ventisquero, Rev. 1
A4: Espacio logotipos mandante / ejecutora
A10: Contrato: | B10: Terminación Mejoramiento Ruta 7 Norte Etapa II Pavimentación, sector Fiordo Queulat–Puente Chucao, tramo km 415,889 a km 433,193, comuna de Cisnes, provincia de Aysén, Región de Aysén | H10: Mes auditado (lista):
A11: Instalación de faenas: | B11: Instalación de Faenas Río Ventisquero | H11: =Config!B3
A12: Empresa ejecutora: | B12: Constructora APIA SpA
A13: Mandante: | B13: Validar con mandante / Inspección Fiscal
A14: Región: | B14: Región de Aysén
A15: Comuna: | B15: Comuna de Cisnes
A16: Duración contractual: | B16: 720 días (mayo 2026 – mayo 2028)
A17: Periodo auditado:
A18: Mes y año de auditoría:
A19: Nombre del auditor:
A20: Cargo:
A21: Fecha de elaboración:
A22: Fecha de revisión:
A23: Fecha de aprobación:
A24: Estado general de la auditoría:
A25: Versión del archivo: | B25: 1.0
A27: ADVERTENCIA: Esta planilla constituye una herramienta de control y seguimiento. No reemplaza la revisión profesional de la normativa vigente, permisos, resoluciones, bases contractuales ni instrucciones de la Inspección Fiscal.

Sheet Config
A1: Parámetros de la auditoría mensual
A2: Mes y año auditado | B2: 05-2026
A3: Referencia mes (celda vinculada) | B3: =B2
A4: Fecha referencia (último día mes) | B4: =FIN.MES(FECHA(VALOR(DERECHA(B2;4));VALOR(IZQUIERDA(B2;2));1);0)
A5: Nombre auditor
A6: Cargo auditor | B6: Encargado ambiental
A8: Ponderación estados (editable)
A9: Cumple | B9: 1
A10: Cumple parcialmente | B10: 0.5
A11: No cumple | B11: 0
A12: En proceso de regularización | B12: 0.25

Sheet Instrucciones
A1: INSTRUCTIVO DE USO — AUDITORÍA TÉCNICO-AMBIENTAL MENSUAL
A3: 1. CÓMO COMPLETAR LA PLANILLA
A4: a) En la hoja Config, seleccione el mes y año auditado.
A5: b) Revise el Catálogo de requisitos (referencia base del PMA Rev. 1).
A6: c) Complete la Matriz de auditoría mensual verificando cada requisito.
A7: d) Registre hallazgos en la hoja correspondiente y vincule el ID de requisito.
A8: e) Actualice permisos, residuos, agua/sanitarios, capacitaciones y registro fotográfico.
A9: f) Revise el Dashboard e Informe mensual automático antes de emitir el informe al mandante.
A11: 2. ESTADOS DE CUMPLIMIENTO
A12: • Cumple: evidencia objetiva demuestra cumplimiento total.
A13: • Cumple parcialmente: cumplimiento incompleto o con deficiencias menores.
A14: • No cumple: incumplimiento verificado.
... A43: Paso 5: Copiar resumen de Informe mensual al informe al mandante / IF.

Sheet Catálogo de requisitos
A1: ID | B1: Componente ambiental | C1: Subcomponente | D1: Etapa | E1: Área/ubicación | F1: Requisito auditable | G1: Medida/obligación/compromiso | H1: Fuente documental | I1: Norma/permiso/referencia | J1: Frecuencia | K1: Indicador/criterio | L1: Método verificación | M1: Resultado esperado | N1: Tipo obligación | O1: Nivel certeza requisito | P1: Ponderación default
A2: REQ-001 | B2: Autorizaciones y permisos | C2: Plan de Manejo | D2: Operación | E2: Oficina ambiental | F2: Disponibilidad del PMA aprobado Rev. 1 | G2: Mantener PMA aprobado disponible para fiscalización | H2: Plan de Manejo Ambiental Específico para Instalación de Faenas Río Ventisquero, Rev. 1 | I2: Validar con normativa vigente o autoridad competente | J2: Mensual | K2: Documento vigente y accesible | L2: Revisión documental | M2: PMA Rev. 1 disponible y legible | N2: Obligación contenida en el Plan de Manejo | O2: Expreso en el Plan de Manejo | P2: 1
A3: REQ-002 | B3: Autorizaciones y permisos | C3: Agua potable | D3: Operación | E3: Sistema AP | F3: Autorización sistema de agua potable particular | G3: Contar con aprobación sanitaria del sistema AP | H3: Plan de Manejo Ambiental Específico para Instalación de Faenas Río Ventisquero, Rev. 1 | I3: DS 594 / Validar con SEREMI de Salud | J3: Mensual | K3: Resolución o certificado vigente | L3: Revisión documental | M3: Autorización vigente disponible | N3: Obligación contenida en el Plan de Manejo | O3: Expreso en el Plan de Manejo | P3: 1
A4: REQ-003 | B4: Autorizaciones y permisos | C4: Alcantarillado | D4: Operación | E4: Sistema AS | F4: Autorización sistema de alcantarillado particular | G4: Contar con aprobación del sistema AS | H4: Plan de Manejo Ambiental Específico para Instalación de Faenas Río Ventisquero, Rev. 1 | I4: Validar con SEREMI de Salud | J4: Mensual | K4: Resolución vigente | L4: Revisión documental | M4: Autorización disponible y vigente | N4: Obligación contenida en el Plan de Manejo | O4: Expreso en el Plan de Manejo | P4: 1
A5: REQ-004 | B5: Autorizaciones y permisos | C5: Bodega RESPEL | D5: Operación | E5: Bodega RESPEL | F5: Autorización bodega de residuos peligrosos | G5: Bodega RESPEL autorizada por autoridad competente | H5: Plan de Manejo Ambiental Específico para Instalación de Faenas Río Ventisquero, Rev. 1 | I5: DS 148 / Validar con autoridad competente | J5: Mensual | K5: Autorización vigente en sitio | L5: Inspección y revisión documental | M5: Autorización RESPEL vigente | N5: Obligación contenida en el Plan de Manejo | O5: Expreso en el Plan de Manejo | P5: 1
A6: REQ-005 | B6: Autorizaciones y permisos | C6: Residuos no peligrosos | D6: Operación | E6: Patio de salvataje | F6: Autorización bodega/patio residuos no peligrosos | G6: Patio o bodega autorizada para RNP | H6: Plan de Manejo Ambiental Específico para Instalación de Faenas Río Ventisquero, Rev. 1 | I6: Validar con normativa vigente o autoridad competente | J6: Mensual | K6: Resolución o antecedente disponible | L6: Revisión documental | M6: Autorización disponible | N6: Obligación contenida en el Plan de Manejo | O6: Derivado del Plan de Manejo | P6: 1
A7: REQ-006 | B7: Autorizaciones y permisos | C7: Control de plagas | D7: Operación | E7: Instalación completa | F7: Resolución sanitaria control de plagas | G7: Servicio de control de plagas con resolución sanitaria | H7: Plan de Manejo Ambiental Específico para Instalación de Faenas Río Ventisquero, Rev. 1 | I7: Validar con SEREMI de Salud | J7: Mensual | K7: Resolución vigente del prestador | L7: Revisión documental | M7: Resolución sanitaria vigente | N7: Obligación contenida en el Plan de Manejo | O7: Expreso en el Plan de Manejo | P7: 1
A8: REQ-007 | B8: Autorizaciones y permisos | C8: Baños y fosas | D8: Operación | E8: Sanitarios | F8: Autorización limpieza baños químicos y fosas sépticas | G8: Empresa autorizada para servicios sanitarios | H8: Plan de Manejo Ambiental Específico para Instalación de Faenas Río Ventisquero, Rev. 1 | I8: Validar con SEREMI de Salud | J8: Mensual | K8: Certificado/resolución del prestador | L8: Revisión documental | M8: Autorización sanitaria vigente | N8: Obligación contenida en el Plan de Manejo | O8: Expreso en el Plan de Manejo | P8: 1
A9: REQ-008 | B9: Autorizaciones y permisos | C9: Agua envasada | D9: Operación | E9: Comedor/bodega | F9: Autorización proveedor agua envasada | G9: Proveedor con autorización sanitaria | H9: Plan de Manejo Ambiental Específico para Instalación de Faenas Río Ventisquero, Rev. 1 | I9: Validar con SEREMI de Salud | J9: Mensual | K9: Certificado vigente | L9: Revisión documental | M9: Autorización disponible | N9: Obligación contenida en el Plan de Manejo | O9: Derivado del Plan de Manejo | P9: 1
A10: REQ-009 | B10: Autorizaciones y permisos | C10: Alimentación | D10: Operación | E10: Comedor | F10: Autorización servicio de alimentación | G10: Servicio de alimentación autorizado | H10: Plan de Manejo Ambiental Específico para Instalación de Faenas Río Ventisquero, Rev. 1 | I10: Validar con SEREMI de Salud | J10: Mensual | K10: Resolución sanitaria vigente | L10: Revisión documental | M10: Autorización vigente | N10: Obligación contenida en el Plan de Manejo | O10: Derivado del Plan de Manejo | P10: 1
A11: REQ-010 | B11: Autorizaciones y permisos | C11: Laboratorio | D11: Operación | E11: Laboratorio | F11: Autorización o antecedentes del laboratorio | G11: Laboratorio con respaldo documental | H11: Plan de Manejo Ambiental Específico para Instalación de Faenas Río Ventisquero, Rev. 1 | I11: Validar con normativa vigente o autoridad competente | J11: Mensual | K11: Antecedentes disponibles | L11: Revisión documental | M11: Documentación disponible | N11: Antecedente documental pendiente | O11: Requiere validación | P11: 1
A12: REQ-011 | B12: Autorizaciones y permisos | C12: Equipos radiactivos | D12: Operación | E12: Bunker/laboratorio | F12: Autorización bunker o almacenamiento equipos radiactivos | G12: Si aplica, contar con autorización CCHEN | H12: Plan de Manejo Ambiental Específico para Instalación de Faenas Río Ventisquero, Rev. 1 | I12: Validar con CCHEN si aplica | J12: Mensual | K12: Autorización o declaración de no aplicabilidad | L12: Revisión documental | M12: Cumplimiento o N/A documentado | N12: Antecedente documental pendiente | O12: Requiere validación | P12: 1
A13: REQ-012 | B13: Autorizaciones y permisos | C13: Grupo generador | D13: Operación | E13: Planta eléctrica | F13: Certificados y antecedentes del grupo generador | G13: Documentación técnica y operacional del generador | H13: Plan de Manejo Ambiental Específico para Instalación de Faenas Río Ventisquero, Rev. 1 | I13: Validar con normativa vigente o autoridad competente | J13: Mensual | K13: Certificados disponibles | L13: Revisión documental e inspección | M13: Antecedentes completos | N13: Obligación contenida en el Plan de Manejo | O13: Derivado del Plan de Manejo | P13: 1
... A84: REQ-083 | B84: Abandono y cierre de la instalación | C84: Informe cierre | D84: Cierre | E84: Oficina ambiental | F84: Entrega informe de cierre al Inspector Fiscal | G84: Informe de cierre elaborado y entregado | H84: Plan de Manejo Ambiental Específico para Instalación de Faenas Río Ventisquero, Rev. 1 | I84: Bases contractuales | J84: Eventual | K84: Informe entregado con folio | L84: Revisión documental | M84: Cierre documentado | N84: Compromiso contractual | O84: Derivado del Plan de Manejo | P84: 1

Sheet Matriz auditoría mensual
A1: ID requisito | B1: Componente ambiental | C1: Subcomponente | D1: Etapa proyecto | E1: Área/ubicación | F1: Requisito auditable | G1: Medida/obligación/compromiso | H1: Fuente documental | I1: Norma/permiso/referencia | J1: Frecuencia control | K1: Indicador/criterio verificación | L1: Método verificación | M1: Resultado esperado | N1: Estado cumplimiento | O1: Nivel hallazgo | P1: Descripción evidencia revisada | Q1: Tipo evidencia | R1: Documento respaldo | S1: Enlace evidencia | T1: Fecha verificación | U1: Responsable verificación | V1: Responsable acción correctiva | W1: Fecha comprometida cierre | X1: Fecha real cierre | Y1: Días atraso | Z1: Acción correctiva/preventiva | AA1: Estado hallazgo | AB1: Observaciones auditor | AC1: Comunicar IF | AD1: Folio comunicación/informe | AE1: Foto antes | AF1: Foto después | AG1: Validación responsable | AH1: Ponderación | AI1: % cumplimiento fila | AJ1: Tipo obligación | AK1: Nivel certeza requisito
A2: REQ-001 | B2: Autorizaciones y permisos | C2: Plan de Manejo | D2: Operación | E2: Oficina ambiental | F2: Disponibilidad del PMA aprobado Rev. 1 | G2: Mantener PMA aprobado disponible para fiscalización | H2: Plan de Manejo Ambiental Específico para Instalación de Faenas Río Ventisquero, Rev. 1 | I2: Validar con normativa vigente o autoridad competente | J2: Mensual | K2: Documento vigente y accesible | L2: Revisión documental | M2: PMA Rev. 1 disponible y legible | Y2: =SI(Y(W2<>"";X2="");HOY()-W2;SI(Y(W2<>"";X2<>"");X2-W2;"")) | AH2: =SI(N2="Cumple";Config!$B$9;SI(N2="Cumple parcialmente";Config!$B$10;SI(N2="No cumple";Config!$B$11;SI(N2="En proceso de regularización";Config!$B$12;SI(N2="No aplica";"NA";"PEND"))))) | AI2: =SI(AH2="NA";"NA";SI(AH2="PEND";"PEND";AH2*100)) | AJ2: Obligación contenida en el Plan de Manejo | AK2: Expreso en el Plan de Manejo
A3: REQ-002 | B3: Autorizaciones y permisos | C3: Agua potable | D3: Operación | E3: Sistema AP | F3: Autorización sistema de agua potable particular | G3: Contar con aprobación sanitaria del sistema AP | H3: Plan de Manejo Ambiental Específico para Instalación de Faenas Río Ventisquero, Rev. 1 | I3: DS 594 / Validar con SEREMI de Salud | J3: Mensual | K3: Resolución o certificado vigente | L3: Revisión documental | M3: Autorización vigente disponible | Y3: =SI(Y(W3<>"";X3="");HOY()-W3;SI(Y(W3<>"";X3<>"");X3-W3;"")) | AH3: =SI(N3="Cumple";Config!$B$9;SI(N3="Cumple parcialmente";Config!$B$10;SI(N3="No cumple";Config!$B$11;SI(N3="En proceso de regularización";Config!$B$12;SI(N3="No aplica";"NA";"PEND"))))) | AI3: =SI(AH3="NA";"NA";SI(AH3="PEND";"PEND";AH3*100)) | AJ3: Obligación contenida en el Plan de Manejo | AK3: Expreso en el Plan de Manejo
A4: REQ-003 | B4: Autorizaciones y permisos | C4: Alcantarillado | D4: Operación | E4: Sistema AS | F4: Autorización sistema de alcantarillado particular | G4: Contar con aprobación del sistema AS | H4: Plan de Manejo Ambiental Específico para Instalación de Faenas Río Ventisquero, Rev. 1 | I4: Validar con SEREMI de Salud | J4: Mensual | K4: Resolución vigente | L4: Revisión documental | M4: Autorización disponible y vigente | Y4: =SI(Y(W4<>"";X4="");HOY()-W4;SI(Y(W4<>"";X4<>"");X4-W4;"")) | AH4: =SI(N4="Cumple";Config!$B$9;SI(N4="Cumple parcialmente";Config!$B$10;SI(N4="No cumple";Config!$B$11;SI(N4="En proceso de regularización";Config!$B$12;SI(N4="No aplica";"NA";"PEND"))))) | AI4: =SI(AH4="NA";"NA";SI(AH4="PEND";"PEND";AH4*100)) | AJ4: Obligación contenida en el Plan de Manejo | AK4: Expreso en el Plan de Manejo
A5: REQ-004 | B5: Autorizaciones y permisos | C5: Bodega RESPEL | D5: Operación | E5: Bodega RESPEL | F5: Autorización bodega de residuos peligrosos | G5: Bodega RESPEL autorizada por autoridad competente | H5: Plan de Manejo Ambiental Específico para Instalación de Faenas Río Ventisquero, Rev. 1 | I5: DS 148 / Validar con autoridad competente | J5: Mensual | K5: Autorización vigente en sitio | L5: Inspección y revisión documental | M5: Autorización RESPEL vigente | Y5: =SI(Y(W5<>"";X5="");HOY()-W5;SI(Y(W5<>"";X5<>"");X5-W5;"")) | AH5: =SI(N5="Cumple";Config!$B$9;SI(N5="Cumple parcialmente";Config!$B$10;SI(N5="No cumple";Config!$B$11;SI(N5="En proceso de regularización";Config!$B$12;SI(N5="No aplica";"NA";"PEND"))))) | AI5: =SI(AH5="NA";"NA";SI(AH5="PEND";"PEND";AH5*100)) | AJ5: Obligación contenida en el Plan de Manejo | AK5: Expreso en el Plan de Manejo
A6: REQ-005 | B6: Autorizaciones y permisos | C6: Residuos no peligrosos | D6: Operación | E6: Patio de salvataje | F6: Autorización bodega/patio residuos no peligrosos | G6: Patio o bodega autorizada para RNP | H6: Plan de Manejo Ambiental Específico para Instalación de Faenas Río Ventisquero, Rev. 1 | I6: Validar con normativa vigente o autoridad competente | J6: Mensual | K6: Resolución o antecedente disponible | L6: Revisión documental | M6: Autorización disponible | Y6: =SI(Y(W6<>"";X6="");HOY()-W6;SI(Y(W6<>"";X6<>"");X6-W6;"")) | AH6: =SI(N6="Cumple";Config!$B$9;SI(N6="Cumple parcialmente";Config!$B$10;SI(N6="No cumple";Config!$B$11;SI(N6="En proceso de regularización";Config!$B$12;SI(N6="No aplica";"NA";"PEND"))))) | AI6: =SI(AH6="NA";"NA";SI(AH6="PEND";"PEND";AH6*100)) | AJ6: Obligación contenida en el Plan de Manejo | AK6: Derivado del Plan de Manejo
A7: REQ-006 | B7: Autorizaciones y permisos | C7: Control de plagas | D7: Operación | E7: Instalación completa | F7: Resolución sanitaria control de plagas | G7: Servicio de control de plagas con resolución sanitaria | H7: Plan de Manejo Ambiental Específico para Instalación de Faenas Río Ventisquero, Rev. 1 | I7: Validar con SEREMI de Salud | J7: Mensual | K7: Resolución vigente del prestador | L7: Revisión documental | M7: Resolución sanitaria vigente | Y7: =SI(Y(W7<>"";X7="");HOY()-W7;SI(Y(W7<>"";X7<>"");X7-W7;"")) | AH7: =SI(N7="Cumple";Config!$B$9;SI(N7="Cumple parcialmente";Config!$B$10;SI(N7="No cumple";Config!$B$11;SI(N7="En proceso de regularización";Config!$B$12;SI(N7="No aplica";"NA";"PEND"))))) | AI7: =SI(AH7="NA";"NA";SI(AH7="PEND";"PEND";AH7*100)) | AJ7: Obligación contenida en el Plan de Manejo | AK7: Expreso en el Plan de Manejo
A8: REQ-007 | B8: Autorizaciones y permisos | C8: Baños y fosas | D8: Operación | E8: Sanitarios | F8: Autorización limpieza baños químicos y fosas sépticas | G8: Empresa autorizada para servicios sanitarios | H8: Plan de Manejo Ambiental Específico para Instalación de Faenas Río Ventisquero, Rev. 1 | I8: Validar con SEREMI de Salud | J8: Mensual | K8: Certificado/resolución del prestador | L8: Revisión documental | M8: Autorización sanitaria vigente | Y8: =SI(Y(W8<>"";X8="");HOY()-W8;SI(Y(W8<>"";X8<>"");X8-W8;"")) | AH8: =SI(N8="Cumple";Config!$B$9;SI(N8="Cumple parcialmente";Config!$B$10;SI(N8="No cumple";Config!$B$11;SI(N8="En proceso de regularización";Config!$B$12;SI(N8="No aplica";"NA";"PEND"))))) | AI8: =SI(AH8="NA";"NA";SI(AH8="PEND";"PEND";AH8*100)) | AJ8: Obligación contenida en el Plan de Manejo | AK8: Expreso en el Plan de Manejo
A9: REQ-008 | B9: Autorizaciones y permisos | C9: Agua envasada | D9: Operación | E9: Comedor/bodega | F9: Autorización proveedor agua envasada | G9: Proveedor con autorización sanitaria | H9: Plan de Manejo Ambiental Específico para Instalación de Faenas Río Ventisquero, Rev. 1 | I9: Validar con SEREMI de Salud | J9: Mensual | K9: Certificado vigente | L9: Revisión documental | M9: Autorización disponible | Y9: =SI(Y(W9<>"";X9="");HOY()-W9;SI(Y(W9<>"";X9<>"");X9-W9;"")) | AH9: =SI(N9="Cumple";Config!$B$9;SI(N9="Cumple parcialmente";Config!$B$10;SI(N9="No cumple";Config!$B$11;SI(N9="En proceso de regularización";Config!$B$12;SI(N9="No aplica";"NA";"PEND"))))) | AI9: =SI(AH9="NA";"NA";SI(AH9="PEND";"PEND";AH9*100)) | AJ9: Obligación contenida en el Plan de Manejo | AK9: Derivado del Plan de Manejo
A10: REQ-009 | B10: Autorizaciones y permisos | C10: Alimentación | D10: Operación | E10: Comedor | F10: Autorización servicio de alimentación | G10: Servicio de alimentación autorizado | H10: Plan de Manejo Ambiental Específico para Instalación de Faenas Río Ventisquero, Rev. 1 | I10: Validar con SEREMI de Salud | J10: Mensual | K10: Resolución sanitaria vigente | L10: Revisión documental | M10: Autorización vigente | Y10: =SI(Y(W10<>"";X10="");HOY()-W10;SI(Y(W10<>"";X10<>"");X10-W10;"")) | AH10: =SI(N10="Cumple";Config!$B$9;SI(N10="Cumple parcialmente";Config!$B$10;SI(N10="No cumple";Config!$B$11;SI(N10="En proceso de regularización";Config!$B$12;SI(N10="No aplica";"NA";"PEND"))))) | AI10: =SI(AH10="NA";"NA";SI(AH10="PEND";"PEND";AH10*100)) | AJ10: Obligación contenida en el Plan de Manejo | AK10: Derivado del Plan de Manejo
A11: REQ-010 | B11: Autorizaciones y permisos | C11: Laboratorio | D11: Operación | E11: Laboratorio | F11: Autorización o antecedentes del laboratorio | G11: Laboratorio con respaldo documental | H11: Plan de Manejo Ambiental Específico para Instalación de Faenas Río Ventisquero, Rev. 1 | I11: Validar con normativa vigente o autoridad competente | J11: Mensual | K11: Antecedentes disponibles | L11: Revisión documental | M11: Documentación disponible | Y11: =SI(Y(W11<>"";X11="");HOY()-W11;SI(Y(W11<>"";X11<>"");X11-W11;"")) | AH11: =SI(N11="Cumple";Config!$B$9;SI(N11="Cumple parcialmente";Config!$B$10;SI(N11="No cumple";Config!$B$11;SI(N11="En proceso de regularización";Config!$B$12;SI(N11="No aplica";"NA";"PEND"))))) | AI11: =SI(AH11="NA";"NA";SI(AH11="PEND";"PEND";AH11*100)) | AJ11: Antecedente documental pendiente | AK11: Requiere validación
A12: REQ-011 | B12: Autorizaciones y permisos | C12: Equipos radiactivos | D12: Operación | E12: Bunker/laboratorio | F12: Autorización bunker o almacenamiento equipos radiactivos | G12: Si aplica, contar con autorización CCHEN | H12: Plan de Manejo Ambiental Específico para Instalación de Faenas Río Ventisquero, Rev. 1 | I12: Validar con CCHEN si aplica | J12: Mensual | K12: Autorización o declaración de no aplicabilidad | L12: Revisión documental | M12: Cumplimiento o N/A documentado | Y12: =SI(Y(W12<>"";X12="");HOY()-W12;SI(Y(W12<>"";X12<>"");X12-W12;"")) | AH12: =SI(N12="Cumple";Config!$B$9;SI(N12="Cumple parcialmente";Config!$B$10;SI(N12="No cumple";Config!$B$11;SI(N12="En proceso de regularización";Config!$B$12;SI(N12="No aplica";"NA";"PEND"))))) | AI12: =SI(AH12="NA";"NA";SI(AH12="PEND";"PEND";AH12*100)) | AJ12: Antecedente documental pendiente | AK12: Requiere validación
A13: REQ-012 | B13: Autorizaciones y permisos | C13: Grupo generador | D13: Operación | E13: Planta eléctrica | F13: Certificados y antecedentes del grupo generador | G13: Documentación técnica y operacional del generador | H13: Plan de Manejo Ambiental Específico para Instalación de Faenas Río Ventisquero, Rev. 1 | I13: Validar con normativa vigente o autoridad competente | J13: Mensual | K13: Certificados disponibles | L13: Revisión documental e inspección | M13: Antecedentes completos | Y13: =SI(Y(W13<>"";X13="");HOY()-W13;SI(Y(W13<>"";X13<>"");X13-W13;"")) | AH13: =SI(N13="Cumple";Config!$B$9;SI(N13="Cumple parcialmente";Config!$B$10;SI(N13="No cumple";Config!$B$11;SI(N13="En proceso de regularización";Config!$B$12;SI(N13="No aplica";"NA";"PEND"))))) | AI13: =SI(AH13="NA";"NA";SI(AH13="PEND";"PEND";AH13*100)) | AJ13: Obligación contenida en el Plan de Manejo | AK13: Derivado del Plan de Manejo
... A84: REQ-083 | B84: Abandono y cierre de la instalación | C84: Informe cierre | D84: Cierre | E84: Oficina ambiental | F84: Entrega informe de cierre al Inspector Fiscal | G84: Informe de cierre elaborado y entregado | H84: Plan de Manejo Ambiental Específico para Instalación de Faenas Río Ventisquero, Rev. 1 | I84: Bases contractuales | J84: Eventual | K84: Informe entregado con folio | L84: Revisión documental | M84: Cierre documentado | Y84: =SI(Y(W84<>"";X84="");HOY()-W84;SI(Y(W84<>"";X84<>"");X84-W84;"")) | AH84: =SI(N84="Cumple";Config!$B$9;SI(N84="Cumple parcialmente";Config!$B$10;SI(N84="No cumple";Config!$B$11;SI(N84="En proceso de regularización";Config!$B$12;SI(N84="No aplica";"NA";"PEND"))))) | AI84: =SI(AH84="NA";"NA";SI(AH84="PEND";"PEND";AH84*100)) | AJ84: Compromiso contractual | AK84: Derivado del Plan de Manejo

Sheet Registro hallazgos
A1: ID hallazgo | B1: Fecha detección | C1: Mes auditoría | D1: ID requisito | E1: Componente ambiental | F1: Descripción hallazgo | G1: Evidencia objetiva | H1: Nivel hallazgo | I1: Riesgo ambiental | J1: Requisito incumplido | K1: Acción inmediata | L1: Acción correctiva definitiva | M1: Responsable | N1: Fecha comprometida | O1: Fecha cierre | P1: Estado | Q1: Días abiertos | R1: Días atraso | S1: Verificación eficacia | T1: Responsable verificar cierre | U1: Evidencia cierre | V1: Comunicar mandante | W1: Folio comunicación | X1: Observaciones
A2: HAL-001 | C2: =Config!B2 | Q2: =SI(Y(B2<>"";O2="");HOY()-B2;SI(Y(B2<>"";O2<>"");O2-B2;"")) | R2: =SI(Y(N2<>"";O2="");HOY()-N2;SI(Y(N2<>"";O2<>"");O2-N2;""))
A3: HAL-002 | C3: =Config!B2 | Q3: =SI(Y(B3<>"";O3="");HOY()-B3;SI(Y(B3<>"";O3<>"");O3-B3;"")) | R3: =SI(Y(N3<>"";O3="");HOY()-N3;SI(Y(N3<>"";O3<>"");O3-N3;""))
A4: HAL-003 | C4: =Config!B2 | Q4: =SI(Y(B4<>"";O4="");HOY()-B4;SI(Y(B4<>"";O4<>"");O4-B4;"")) | R4: =SI(Y(N4<>"";O4="");HOY()-N4;SI(Y(N4<>"";O4<>"");O4-N4;""))
A5: HAL-004 | C5: =Config!B2 | Q5: =SI(Y(B5<>"";O5="");HOY()-B5;SI(Y(B5<>"";O5<>"");O5-B5;"")) | R5: =SI(Y(N5<>"";O5="");HOY()-N5;SI(Y(N5<>"";O5<>"");O5-N5;""))
A6: HAL-005 | C6: =Config!B2 | Q6: =SI(Y(B6<>"";O6="");HOY()-B6;SI(Y(B6<>"";O6<>"");O6-B6;"")) | R6: =SI(Y(N6<>"";O6="");HOY()-N6;SI(Y(N6<>"";O6<>"");O6-N6;""))
A7: HAL-006 | C7: =Config!B2 | Q7: =SI(Y(B7<>"";O7="");HOY()-B7;SI(Y(B7<>"";O7<>"");O7-B7;"")) | R7: =SI(Y(N7<>"";O7="");HOY()-N7;SI(Y(N7<>"";O7<>"");O7-N7;""))
A8: HAL-007 | C8: =Config!B2 | Q8: =SI(Y(B8<>"";O8="");HOY()-B8;SI(Y(B8<>"";O8<>"");O8-B8;"")) | R8: =SI(Y(N8<>"";O8="");HOY()-N8;SI(Y(N8<>"";O8<>"");O8-N8;""))
A9: HAL-008 | C9: =Config!B2 | Q9: =SI(Y(B9<>"";O9="");HOY()-B9;SI(Y(B9<>"";O9<>"");O9-B9;"")) | R9: =SI(Y(N9<>"";O9="");HOY()-N9;SI(Y(N9<>"";O9<>"");O9-N9;""))
A10: HAL-009 | C10: =Config!B2 | Q10: =SI(Y(B10<>"";O10="");HOY()-B10;SI(Y(B10<>"";O10<>"");O10-B10;"")) | R10: =SI(Y(N10<>"";O10="");HOY()-N10;SI(Y(N10<>"";O10<>"");O10-N10;""))
A11: HAL-010 | C11: =Config!B2 | Q11: =SI(Y(B11<>"";O11="");HOY()-B11;SI(Y(B11<>"";O11<>"");O11-B11;"")) | R11: =SI(Y(N11<>"";O11="");HOY()-N11;SI(Y(N11<>"";O11<>"");O11-N11;""))
A12: HAL-011 | C12: =Config!B2 | Q12: =SI(Y(B12<>"";O12="");HOY()-B12;SI(Y(B12<>"";O12<>"");O12-B12;"")) | R12: =SI(Y(N12<>"";O12="");HOY()-N12;SI(Y(N12<>"";O12<>"");O12-N12;""))
A13: HAL-012 | C13: =Config!B2 | Q13: =SI(Y(B13<>"";O13="");HOY()-B13;SI(Y(B13<>"";O13<>"");O13-B13;"")) | R13: =SI(Y(N13<>"";O13="");HOY()-N13;SI(Y(N13<>"";O13<>"");O13-N13;""))
A14: HAL-013 | C14: =Config!B2 | Q14: =SI(Y(B14<>"";O14="");HOY()-B14;SI(Y(B14<>"";O14<>"");O14-B14;"")) | R14: =SI(Y(N14<>"";O14="");HOY()-N14;SI(Y(N14<>"";O14<>"");O14-N14;""))
A15: HAL-014 | C15: =Config!B2 | Q15: =SI(Y(B15<>"";O15="");HOY()-B15;SI(Y(B15<>"";O15<>"");O15-B15;"")) | R15: =SI(Y(N15<>"";O15="");HOY()-N15;SI(Y(N15<>"";O15<>"");O15-N15;""))
A16: HAL-015 | C16: =Config!B2 | Q16: =SI(Y(B16<>"";O16="");HOY()-B16;SI(Y(B16<>"";O16<>"");O16-B16;"")) | R16: =SI(Y(N16<>"";O16="");HOY()-N16;SI(Y(N16<>"";O16<>"");O16-N16;""))
A17: HAL-016 | C17: =Config!B2 | Q17: =SI(Y(B17<>"";O17="");HOY()-B17;SI(Y(B17<>"";O17<>"");O17-B17;"")) | R17: =SI(Y(N17<>"";O17="");HOY()-N17;SI(Y(N17<>"";O17<>"");O17-N17;""))
A18: HAL-017 | C18: =Config!B2 | Q18: =SI(Y(B18<>"";O18="");HOY()-B18;SI(Y(B18<>"";O18<>"");O18-B18;"")) | R18: =SI(Y(N18<>"";O18="");HOY()-N18;SI(Y(N18<>"";O18<>"");O18-N18;""))
A19: HAL-018 | C19: =Config!B2 | Q19: =SI(Y(B19<>"";O19="");HOY()-B19;SI(Y(B19<>"";O19<>"");O19-B19;"")) | R19: =SI(Y(N19<>"";O19="");HOY()-N19;SI(Y(N19<>"";O19<>"");O19-N19;""))
A20: HAL-019 | C20: =Config!B2 | Q20: =SI(Y(B20<>"";O20="");HOY()-B20;SI(Y(B20<>"";O20<>"");O20-B20;"")) | R20: =SI(Y(N20<>"";O20="");HOY()-N20;SI(Y(N20<>"";O20<>"");O20-N20;""))
A21: HAL-020 | C21: =Config!B2 | Q21: =SI(Y(B21<>"";O21="");HOY()-B21;SI(Y(B21<>"";O21<>"");O21-B21;"")) | R21: =SI(Y(N21<>"";O21="");HOY()-N21;SI(Y(N21<>"";O21<>"");O21-N21;""))
A22: HAL-021 | C22: =Config!B2 | Q22: =SI(Y(B22<>"";O22="");HOY()-B22;SI(Y(B22<>"";O22<>"");O22-B22;"")) | R22: =SI(Y(N22<>"";O22="");HOY()-N22;SI(Y(N22<>"";O22<>"");O22-N22;""))
A23: HAL-022 | C23: =Config!B2 | Q23: =SI(Y(B23<>"";O23="");HOY()-B23;SI(Y(B23<>"";O23<>"");O23-B23;"")) | R23: =SI(Y(N23<>"";O23="");HOY()-N23;SI(Y(N23<>"";O23<>"");O23-N23;""))
A24: HAL-023 | C24: =Config!B2 | Q24: =SI(Y(B24<>"";O24="");HOY()-B24;SI(Y(B24<>"";O24<>"");O24-B24;"")) | R24: =SI(Y(N24<>"";O24="");HOY()-N24;SI(Y(N24<>"";O24<>"");O24-N24;""))
A25: HAL-024 | C25: =Config!B2 | Q25: =SI(Y(B25<>"";O25="");HOY()-B25;SI(Y(B25<>"";O25<>"");O25-B25;"")) | R25: =SI(Y(N25<>"";O25="");HOY()-N25;SI(Y(N25<>"";O25<>"");O25-N25;""))
A26: HAL-025 | C26: =Config!B2 | Q26: =SI(Y(B26<>"";O26="");HOY()-B26;SI(Y(B26<>"";O26<>"");O26-B26;"")) | R26: =SI(Y(N26<>"";O26="");HOY()-N26;SI(Y(N26<>"";O26<>"");O26-N26;""))
A27: HAL-026 | C27: =Config!B2 | Q27: =SI(Y(B27<>"";O27="");HOY()-B27;SI(Y(B27<>"";O27<>"");O27-B27;"")) | R27: =SI(Y(N27<>"";O27="");HOY()-N27;SI(Y(N27<>"";O27<>"");O27-N27;""))
A28: HAL-027 | C28: =Config!B2 | Q28: =SI(Y(B28<>"";O28="");HOY()-B28;SI(Y(B28<>"";O28<>"");O28-B28;"")) | R28: =SI(Y(N28<>"";O28="");HOY()-N28;SI(Y(N28<>"";O28<>"");O28-N28;""))
A29: HAL-028 | C29: =Config!B2 | Q29: =SI(Y(B29<>"";O29="");HOY()-B29;SI(Y(B29<>"";O29<>"");O29-B29;"")) | R29: =SI(Y(N29<>"";O29="");HOY()-N29;SI(Y(N29<>"";O29<>"");O29-N29;""))
A30: HAL-029 | C30: =Config!B2 | Q30: =SI(Y(B30<>"";O30="");HOY()-B30;SI(Y(B30<>"";O30<>"");O30-B30;"")) | R30: =SI(Y(N30<>"";O30="");HOY()-N30;SI(Y(N30<>"";O30<>"");O30-N30;""))
A31: HAL-030 | C31: =Config!B2 | Q31: =SI(Y(B31<>"";O31="");HOY()-B31;SI(Y(B31<>"";O31<>"");O31-B31;"")) | R31: =SI(Y(N31<>"";O31="");HOY()-N31;SI(Y(N31<>"";O31<>"");O31-N31;""))
A32: HAL-031 | C32: =Config!B2 | Q32: =SI(Y(B32<>"";O32="");HOY()-B32;SI(Y(B32<>"";O32<>"");O32-B32;"")) | R32: =SI(Y(N32<>"";O32="");HOY()-N32;SI(Y(N32<>"";O32<>"");O32-N32;""))
A33: HAL-032 | C33: =Config!B2 | Q33: =SI(Y(B33<>"";O33="");HOY()-B33;SI(Y(B33<>"";O33<>"");O33-B33;"")) | R33: =SI(Y(N33<>"";O33="");HOY()-N33;SI(Y(N33<>"";O33<>"");O33-N33;""))
A34: HAL-033 | C34: =Config!B2 | Q34: =SI(Y(B34<>"";O34="");HOY()-B34;SI(Y(B34<>"";O34<>"");O34-B34;"")) | R34: =SI(Y(N34<>"";O34="");HOY()-N34;SI(Y(N34<>"";O34<>"");O34-N34;""))
A35: HAL-034 | C35: =Config!B2 | Q35: =SI(Y(B35<>"";O35="");HOY()-B35;SI(Y(B35<>"";O35<>"");O35-B35;"")) | R35: =SI(Y(N35<>"";O35="");HOY()-N35;SI(Y(N35<>"";O35<>"");O35-N35;""))
A36: HAL-035 | C36: =Config!B2 | Q36: =SI(Y(B36<>"";O36="");HOY()-B36;SI(Y(B36<>"";O36<>"");O36-B36;"")) | R36: =SI(Y(N36<>"";O36="");HOY()-N36;SI(Y(N36<>"";O36<>"");O36-N36;""))
A37: HAL-036 | C37: =Config!B2 | Q37: =SI(Y(B37<>"";O37="");HOY()-B37;SI(Y(B37<>"";O37<>"");O37-B37;"")) | R37: =SI(Y(N37<>"";O37="");HOY()-N37;SI(Y(N37<>"";O37<>"");O37-N37;""))
A38: HAL-037 | C38: =Config!B2 | Q38: =SI(Y(B38<>"";O38="");HOY()-B38;SI(Y(B38<>"";O38<>"");O38-B38;"")) | R38: =SI(Y(N38<>"";O38="");HOY()-N38;SI(Y(N38<>"";O38<>"");O38-N38;""))
A39: HAL-038 | C39: =Config!B2 | Q39: =SI(Y(B39<>"";O39="");HOY()-B39;SI(Y(B39<>"";O39<>"");O39-B39;"")) | R39: =SI(Y(N39<>"";O39="");HOY()-N39;SI(Y(N39<>"";O39<>"");O39-N39;""))
A40: HAL-039 | C40: =Config!B2 | Q40: =SI(Y(B40<>"";O40="");HOY()-B40;SI(Y(B40<>"";O40<>"");O40-B40;"")) | R40: =SI(Y(N40<>"";O40="");HOY()-N40;SI(Y(N40<>"";O40<>"");O40-N40;""))
...

Sheet Control permisos
A1: ID documental | B1: Tipo documento | C1: Documento/permiso | D1: Materia | E1: Autoridad emisora | F1: Titular | G1: N° resolución/certificado | H1: Fecha emisión | I1: Fecha vencimiento | J1: Vigencia (días rest.) | K1: Estado documental (auto) | L1: Responsable | M1: Ubicación archivo | N1: Enlace digital | O1: Fecha última revisión | P1: Observaciones
A2: DOC-001 | B2: Permiso/Aprobación | C2: Plan de Manejo Instalación de Faenas Rev. 1 | D2: Ambiental | E2: Validar con autoridad competente | F2: Constructora APIA SpA | G2: Validar número | H2: 01-05-2026 | I2: 01-05-2028 | J2: =SI(I2="";"";I2-HOY()) | K2: =SI(I2="";"No disponible";SI(J2<0;"Vencido";SI(J2<=30;"Por vencer en 30 días";SI(J2<=60;"Por vencer en 60 días";"Vigente"))))
A3: DOC-002 | B3: Permiso/Aprobación | C3: Sistema de agua potable particular | D3: Sanitaria | E3: SEREMI Salud Aysén | F3: Constructora APIA SpA | G3: Validar número | H3: 01-05-2026 | I3: 01-05-2028 | J3: =SI(I3="";"";I3-HOY()) | K3: =SI(I3="";"No disponible";SI(J3<0;"Vencido";SI(J3<=30;"Por vencer en 30 días";SI(J3<=60;"Por vencer en 60 días";"Vigente"))))
A4: DOC-003 | B4: Permiso/Aprobación | C4: Sistema de alcantarillado particular | D4: Sanitaria | E4: SEREMI Salud Aysén | F4: Constructora APIA SpA | G4: Validar número | H4: 01-05-2026 | I4: 01-05-2028 | J4: =SI(I4="";"";I4-HOY()) | K4: =SI(I4="";"No disponible";SI(J4<0;"Vencido";SI(J4<=30;"Por vencer en 30 días";SI(J4<=60;"Por vencer en 60 días";"Vigente"))))
A5: DOC-004 | B5: Permiso/Aprobación | C5: Autorización bodega RESPEL | D5: Ambiental/RESPEL | E5: Validar con autoridad competente | F5: Constructora APIA SpA | G5: Validar número | H5: 01-05-2026 | I5: 01-05-2028 | J5: =SI(I5="";"";I5-HOY()) | K5: =SI(I5="";"No disponible";SI(J5<0;"Vencido";SI(J5<=30;"Por vencer en 30 días";SI(J5<=60;"Por vencer en 60 días";"Vigente"))))
A6: DOC-005 | B6: Resolución sanitaria | C6: Control de plagas | D6: Sanitaria | E6: SEREMI Salud | F6: Empresa prestadora | G6: Validar número | H6: 01-05-2026 | I6: 01-05-2028 | J6: =SI(I6="";"";I6-HOY()) | K6: =SI(I6="";"No disponible";SI(J6<0;"Vencido";SI(J6<=30;"Por vencer en 30 días";SI(J6<=60;"Por vencer en 60 días";"Vigente"))))
A7: DOC-006 | B7: Certificado | C7: Limpieza baños químicos y fosas sépticas | D7: Sanitaria | E7: SEREMI Salud | F7: Empresa prestadora | G7: Validar número | H7: 01-05-2026 | I7: 01-05-2028 | J7: =SI(I7="";"";I7-HOY()) | K7: =SI(I7="";"No disponible";SI(J7<0;"Vencido";SI(J7<=30;"Por vencer en 30 días";SI(J7<=60;"Por vencer en 60 días";"Vigente"))))
A8: DOC-007 | B8: Certificado | C8: Análisis agua potable | D8: Sanitaria | E8: Laboratorio autorizado | F8: Constructora APIA SpA | G8: Validar número | H8: 01-05-2026 | I8: 31-05-2026 | J8: =SI(I8="";"";I8-HOY()) | K8: =SI(I8="";"No disponible";SI(J8<0;"Vencido";SI(J8<=30;"Por vencer en 30 días";SI(J8<=60;"Por vencer en 60 días";"Vigente"))))
A9: DOC-008 | B9: Permiso | C9: Transporte RESPEL | D9: Ambiental | E9: Validar con autoridad competente | F9: Transportista RESPEL | G9: Validar número | H9: 01-05-2026 | I9: 01-05-2028 | J9: =SI(I9="";"";I9-HOY()) | K9: =SI(I9="";"No disponible";SI(J9<0;"Vencido";SI(J9<=30;"Por vencer en 30 días";SI(J9<=60;"Por vencer en 60 días";"Vigente"))))
A10: DOC-009 | B10: Declaración | C10: Declaración anual emisiones RETC | D10: Atmosférica | E10: MMA / RETC | F10: Constructora APIA SpA | G10: Validar folio | H10: 01-01-2027 | I10: 30-04-2027 | J10: =SI(I10="";"";I10-HOY()) | K10: =SI(I10="";"No disponible";SI(J10<0;"Vencido";SI(J10<=30;"Por vencer en 30 días";SI(J10<=60;"Por vencer en 60 días";"Vigente"))))
A11: DOC-010 | B11: Certificado | C11: Disposición final residuos domiciliarios | D11: Residuos | E11: Vertedero autorizado | F11: Empresa transportista | G11: Validar número | H11: 01-05-2026 | I11: 31-05-2026 | J11: =SI(I11="";"";I11-HOY()) | K11: =SI(I11="";"No disponible";SI(J11<0;"Vencido";SI(J11<=30;"Por vencer en 30 días";SI(J11<=60;"Por vencer en 60 días";"Vigente"))))
J12: =SI(I12="";"";I12-HOY()) | K12: =SI(I12="";"No disponible";SI(J12<0;"Vencido";SI(J12<=30;"Por vencer en 30 días";SI(J12<=60;"Por vencer en 60 días";"Vigente"))))
J13: =SI(I13="";"";I13-HOY()) | K13: =SI(I13="";"No disponible";SI(J13<0;"Vencido";SI(J13<=30;"Por vencer en 30 días";SI(J13<=60;"Por vencer en 60 días";"Vigente"))))
J14: =SI(I14="";"";I14-HOY()) | K14: =SI(I14="";"No disponible";SI(J14<0;"Vencido";SI(J14<=30;"Por vencer en 30 días";SI(J14<=60;"Por vencer en 60 días";"Vigente"))))
J15: =SI(I15="";"";I15-HOY()) | K15: =SI(I15="";"No disponible";SI(J15<0;"Vencido";SI(J15<=30;"Por vencer en 30 días";SI(J15<=60;"Por vencer en 60 días";"Vigente"))))
J16: =SI(I16="";"";I16-HOY()) | K16: =SI(I16="";"No disponible";SI(J16<0;"Vencido";SI(J16<=30;"Por vencer en 30 días";SI(J16<=60;"Por vencer en 60 días";"Vigente"))))
J17: =SI(I17="";"";I17-HOY()) | K17: =SI(I17="";"No disponible";SI(J17<0;"Vencido";SI(J17<=30;"Por vencer en 30 días";SI(J17<=60;"Por vencer en 60 días";"Vigente"))))
J18: =SI(I18="";"";I18-HOY()) | K18: =SI(I18="";"No disponible";SI(J18<0;"Vencido";SI(J18<=30;"Por vencer en 30 días";SI(J18<=60;"Por vencer en 60 días";"Vigente"))))
J19: =SI(I19="";"";I19-HOY()) | K19: =SI(I19="";"No disponible";SI(J19<0;"Vencido";SI(J19<=30;"Por vencer en 30 días";SI(J19<=60;"Por vencer en 60 días";"Vigente"))))
J20: =SI(I20="";"";I20-HOY()) | K20: =SI(I20="";"No disponible";SI(J20<0;"Vencido";SI(J20<=30;"Por vencer en 30 días";SI(J20<=60;"Por vencer en 60 días";"Vigente"))))
J21: =SI(I21="";"";I21-HOY()) | K21: =SI(I21="";"No disponible";SI(J21<0;"Vencido";SI(J21<=30;"Por vencer en 30 días";SI(J21<=60;"Por vencer en 60 días";"Vigente"))))
J22: =SI(I22="";"";I22-HOY()) | K22: =SI(I22="";"No disponible";SI(J22<0;"Vencido";SI(J22<=30;"Por vencer en 30 días";SI(J22<=60;"Por vencer en 60 días";"Vigente"))))
J23: =SI(I23="";"";I23-HOY()) | K23: =SI(I23="";"No disponible";SI(J23<0;"Vencido";SI(J23<=30;"Por vencer en 30 días";SI(J23<=60;"Por vencer en 60 días";"Vigente"))))
... J30: =SI(I30="";"";I30-HOY()) | K30: =SI(I30="";"No disponible";SI(J30<0;"Vencido";SI(J30<=30;"Por vencer en 30 días";SI(J30<=60;"Por vencer en 60 días";"Vigente"))))

Sheet Registro residuos
A1: Mes | B1: Fecha | C1: Área generadora | D1: Tipo residuo | E1: Clasificación | F1: Peligrosidad | G1: Código/descripción | H1: Cantidad | I1: Unidad | J1: Contenedor | K1: Fecha retiro | L1: Transportista | M1: Autorización transportista | N1: Destino final | O1: Autorización destino | P1: N° guía/manifiesto/certificado | Q1: Evidencia | R1: Observaciones
A2: =Config!B2

Sheet Agua y sanitarios
A1: Mes | B1: Fecha | C1: Tipo control | D1: Sistema/instalación | E1: Agua potable | F1: Cloro residual | G1: Resultado análisis | H1: Limpieza fosa séptica | I1: Limpieza baño químico | J1: Limpieza cámara desgrasadora | K1: Empresa prestadora | L1: N° resolución sanitaria | M1: Certificado/respaldo | N1: Resultado | O1: Observaciones
A2: =Config!B2

Sheet Capacitaciones
A1: Fecha | B1: Tema | C1: Tipo capacitación | D1: Relator | E1: Cargo | F1: Empresa | G1: N° asistentes | H1: Lista asistencia | I1: Evaluación | J1: Evidencia | K1: Observaciones

Sheet Registro fotográfico
A1: ID foto | B1: Fecha | C1: Mes | D1: Ubicación | E1: Componente ambiental | F1: Descripción | G1: Tipo evidencia | H1: Antes/después | I1: Nombre archivo | J1: Enlace | K1: Coordenadas | L1: Responsable | M1: Observaciones
A2: FOT-001 | C2: =Config!B2
A3: FOT-002 | C3: =Config!B2
A4: FOT-003 | C4: =Config!B2
A5: FOT-004 | C5: =Config!B2
A6: FOT-005 | C6: =Config!B2
A7: FOT-006 | C7: =Config!B2
A8: FOT-007 | C8: =Config!B2
A9: FOT-008 | C9: =Config!B2
A10: FOT-009 | C10: =Config!B2
A11: FOT-010 | C11: =Config!B2
A12: FOT-011 | C12: =Config!B2
A13: FOT-012 | C13: =Config!B2
A14: FOT-013 | C14: =Config!B2
A15: FOT-014 | C15: =Config!B2
A16: FOT-015 | C16: =Config!B2
A17: FOT-016 | C17: =Config!B2
A18: FOT-017 | C18: =Config!B2
A19: FOT-018 | C19: =Config!B2
A20: FOT-019 | C20: =Config!B2
A21: FOT-020 | C21: =Config!B2
A22: FOT-021 | C22: =Config!B2
A23: FOT-022 | C23: =Config!B2
A24: FOT-023 | C24: =Config!B2
A25: FOT-024 | C25: =Config!B2
A26: FOT-025 | C26: =Config!B2
A27: FOT-026 | C27: =Config!B2
A28: FOT-027 | C28: =Config!B2
A29: FOT-028 | C29: =Config!B2
A30: FOT-029 | C30: =Config!B2
A31: FOT-030 | C31: =Config!B2
A32: FOT-031 | C32: =Config!B2
A33: FOT-032 | C33: =Config!B2
A34: FOT-033 | C34: =Config!B2
A35: FOT-034 | C35: =Config!B2
A36: FOT-035 | C36: =Config!B2
A37: FOT-036 | C37: =Config!B2
A38: FOT-037 | C38: =Config!B2
A39: FOT-038 | C39: =Config!B2
A40: FOT-039 | C40: =Config!B2
...

Sheet Dashboard
A1: DASHBOARD MENSUAL — AUDITORÍA AMBIENTAL
A2: Periodo: | B2: =Config!B2
A4: % cumplimiento total | B4: =SI.ERROR((CONTAR.SI('Matriz auditoría mensual'!N2:N84;"Cumple")*Config!$B$9+CONTAR.SI('Matriz auditoría mensual'!N2:N84;"Cumple parcialmente")*Config!$B$10+CONTAR.SI('Matriz auditoría mensual'!N2:N84;"No cumple")*Config!$B$11+CONTAR.SI('Matriz auditoría mensual'!N2:N84;"En proceso de regularización")*Config!$B$12)/(CONTAR('Matriz auditoría mensual'!N2:N84)-CONTAR.SI('Matriz auditoría mensual'!N2:N84;"No aplica")-CONTAR.SI('Matriz auditoría mensual'!N2:N84;"Pendiente de verificación"));0) | D4: Estado | E4: Cantidad
A5: % requisitos cumplidos | B5: =CONTAR.SI('Matriz auditoría mensual'!N2:N84;"Cumple") | D5: Cumple | E5: =CONTAR.SI('Matriz auditoría mensual'!N2:N84;"Cumple")
A6: % cumplimiento parcial | B6: =CONTAR.SI('Matriz auditoría mensual'!N2:N84;"Cumple parcialmente") | D6: Cumple parcialmente | E6: =CONTAR.SI('Matriz auditoría mensual'!N2:N84;"Cumple parcialmente")
A7: Incumplimientos (No cumple) | B7: =CONTAR.SI('Matriz auditoría mensual'!N2:N84;"No cumple") | D7: No cumple | E7: =CONTAR.SI('Matriz auditoría mensual'!N2:N84;"No cumple")
A8: Hallazgos críticos | B8: =CONTAR.SI.CONJUNTO('Registro hallazgos'!H:H;"Crítico";'Registro hallazgos'!P:P;"<>Cerrado") | D8: Pendiente | E8: =CONTAR.SI('Matriz auditoría mensual'!N2:N84;"Pendiente de verificación")
A9: Hallazgos mayores | B9: =CONTAR.SI.CONJUNTO('Registro hallazgos'!H:H;"Mayor";'Registro hallazgos'!P:P;"<>Cerrado") | D9: En regularización | E9: =CONTAR.SI('Matriz auditoría mensual'!N2:N84;"En proceso de regularización")
A10: Hallazgos abiertos | B10: =CONTAR.SI('Registro hallazgos'!P:P;"Abierto")+CONTAR.SI('Registro hallazgos'!P:P;"En tratamiento")
A11: Hallazgos vencidos | B11: =CONTAR.SI.CONJUNTO('Registro hallazgos'!N:N;"<"&HOY();'Registro hallazgos'!O:O;"")
A12: Documentos vigentes | B12: =CONTAR.SI('Control permisos'!K:K;"Vigente") | D12: Nivel hallazgo | E12: Cantidad
A13: Documentos por vencer (≤60 d) | B13: =CONTAR.SI('Control permisos'!K:K;"Por vencer en 30 días")+CONTAR.SI('Control permisos'!K:K;"Por vencer en 60 días") | D13: Crítico | E13: =CONTAR.SI('Registro hallazgos'!H:H;"Crítico")
A14: Documentos vencidos | B14: =CONTAR.SI('Control permisos'!K:K;"Vencido") | D14: Mayor | E14: =CONTAR.SI('Registro hallazgos'!H:H;"Mayor")
A15: Capacitaciones del mes | B15: =CONTAR('Capacitaciones'!A2:A200) | D15: Menor | E15: =CONTAR.SI('Registro hallazgos'!H:H;"Menor")
A16: Reclamos comunitarios | B16: =CONTAR.SI('Matriz auditoría mensual'!AB:AB;"*reclamo*") | D16: Observación | E16: =CONTAR.SI('Registro hallazgos'!H:H;"Observación")
A17: Incidentes ambientales | B17: =CONTAR.SI('Registro hallazgos'!H:H;"Crítico") | D17: Buena práctica | E17: =CONTAR.SI('Registro hallazgos'!H:H;"Buena práctica")
A18: Controles ejecutados | B18: =CONTAR('Matriz auditoría mensual'!T2:T84)
A19: Semáforo cumplimiento | B19: =SI(B4>=0,9;"VERDE";SI(B4>=0,7;"AMARILLO";"ROJO"))

Sheet Informe mensual
A1: INFORME MENSUAL AUTOMÁTICO — RESUMEN EJECUTIVO
A3: Periodo auditado: | B3: =Config!B2
A4: Estado general: | B4: =Dashboard!B19
A5: Porcentaje cumplimiento: | B5: =Dashboard!B4
A6: Principales cumplimientos: | B6: (Completar manualmente a partir de la matriz)
A7: Principales incumplimientos: | B7: (Completar manualmente a partir de la matriz)
A8: Hallazgos críticos y mayores: | B8: =Dashboard!B8 & " críticos; " & Dashboard!B9 & " mayores"
A9: Acciones correctivas pendientes: | B9: =Dashboard!B10
A10: Documentos vencidos o por vencer: | B10: =Dashboard!B13 & " por vencer; " & Dashboard!B14 & " vencidos"
A11: Residuos generados: | B11: (Ver hoja Registro residuos)
A12: Capacitaciones realizadas: | B12: =Dashboard!B15
A13: Incidentes ambientales: | B13: (Ver Registro hallazgos / Matriz REQ-038)
A14: Reclamos comunitarios: | B14: (Ver Matriz REQ-027, REQ-078)
A15: Recomendaciones:
A16: Conclusión del auditor:
A17: Nombre y firma: | B17: =Config!B5
